18:35:47  [INFO]  === FROG Ver 3.1 – refactored ===
18:35:47  [ERROR]  Fatal error: could not open port 'COM3': PermissionError(13, 'アクセスが拒否されました。', None, 5)
Traceback (most recent call last):
  File "c:\Users\KITAYAMA\KITAYAMA_FROG\bata\FROG_Ver3.1_refactored.py", line 232, in main
    frog_scan(cfg, args)
  File "c:\Users\KITAYAMA\KITAYAMA_FROG\bata\FROG_Ver3.1_refactored.py", line 174, in frog_scan
    stage = StageController(cfg.stage.port, cfg.stage.baudrate, logger)
            ^^^^^^^^^^^^^^^^^^^^^^^^^^^^^^^^^^^^^^^^^^^^^^^^^^^^^^^^^^^
  File "c:\Users\KITAYAMA\KITAYAMA_FROG\bata\FROG_Ver3.1_refactored.py", line 100, in __init__
    self.ser = serial.Serial(port, baudrate, timeout=1)
               ^^^^^^^^^^^^^^^^^^^^^^^^^^^^^^^^^^^^^^^^
  File "C:\Users\KITAYAMA\AppData\Local\Packages\PythonSoftwareFoundation.Python.3.11_qbz5n2kfra8p0\LocalCache\local-packages\Python311\site-packages\serial\serialwin32.py", line 33, in __init__
    super(Serial, self).__init__(*args, **kwargs)
  File "C:\Users\KITAYAMA\AppData\Local\Packages\PythonSoftwareFoundation.Python.3.11_qbz5n2kfra8p0\LocalCache\local-packages\Python311\site-packages\serial\serialutil.py", line 244, in __init__
    self.open()
  File "C:\Users\KITAYAMA\AppData\Local\Packages\PythonSoftwareFoundation.Python.3.11_qbz5n2kfra8p0\LocalCache\local-packages\Python311\site-packages\serial\serialwin32.py", line 64, in open
    raise SerialException("could not open port {!r}: {!r}".format(self.portstr, ctypes.WinError()))
serial.serialutil.SerialException: could not open port 'COM3': PermissionError(13, 'アクセスが拒否されました。', None, 5)
18:35:47  [INFO]  Bye.
